[2023-03-05T11:42:08.946+0000] {taskinstance.py:1083} INFO - Dependencies all met for <TaskInstance: transform_fact_user.task_2 manual__2023-03-05T11:42:07.248614+00:00 [queued]>
[2023-03-05T11:42:08.954+0000] {taskinstance.py:1083} INFO - Dependencies all met for <TaskInstance: transform_fact_user.task_2 manual__2023-03-05T11:42:07.248614+00:00 [queued]>
[2023-03-05T11:42:08.955+0000] {taskinstance.py:1279} INFO - 
--------------------------------------------------------------------------------
[2023-03-05T11:42:08.957+0000] {taskinstance.py:1280} INFO - Starting attempt 1 of 1
[2023-03-05T11:42:08.958+0000] {taskinstance.py:1281} INFO - 
--------------------------------------------------------------------------------
[2023-03-05T11:42:08.968+0000] {taskinstance.py:1300} INFO - Executing <Task(BashOperator): task_2> on 2023-03-05 11:42:07.248614+00:00
[2023-03-05T11:42:08.977+0000] {standard_task_runner.py:55} INFO - Started process 2791 to run task
[2023-03-05T11:42:08.980+0000] {standard_task_runner.py:82} INFO - Running: ['***', 'tasks', 'run', 'transform_fact_user', 'task_2', 'manual__2023-03-05T11:42:07.248614+00:00', '--job-id', '45', '--raw', '--subdir', 'DAGS_FOLDER/transform_fact_user.py', '--cfg-path', '/tmp/tmpg44y3oyl']
[2023-03-05T11:42:08.982+0000] {standard_task_runner.py:83} INFO - Job 45: Subtask task_2
[2023-03-05T11:42:09.048+0000] {task_command.py:388} INFO - Running <TaskInstance: transform_fact_user.task_2 manual__2023-03-05T11:42:07.248614+00:00 [running]> on host 0997e433a2b7
[2023-03-05T11:42:09.103+0000] {taskinstance.py:1509} INFO - Exporting the following env vars:
AIRFLOW_CTX_DAG_OWNER=***
AIRFLOW_CTX_DAG_ID=transform_fact_user
AIRFLOW_CTX_TASK_ID=task_2
AIRFLOW_CTX_EXECUTION_DATE=2023-03-05T11:42:07.248614+00:00
AIRFLOW_CTX_TRY_NUMBER=1
AIRFLOW_CTX_DAG_RUN_ID=manual__2023-03-05T11:42:07.248614+00:00
[2023-03-05T11:42:09.105+0000] {subprocess.py:63} INFO - Tmp dir root location: 
 /tmp
[2023-03-05T11:42:09.107+0000] {subprocess.py:75} INFO - Running command: ['/bin/bash', '-c', 'ls home']
[2023-03-05T11:42:09.120+0000] {subprocess.py:86} INFO - Output:
[2023-03-05T11:42:09.125+0000] {subprocess.py:93} INFO - ls: cannot access 'home': No such file or directory
[2023-03-05T11:42:09.126+0000] {subprocess.py:97} INFO - Command exited with return code 2
[2023-03-05T11:42:09.138+0000] {taskinstance.py:1768} ERROR - Task failed with exception
Traceback (most recent call last):
  File "/home/airflow/.local/lib/python3.7/site-packages/airflow/operators/bash.py", line 197, in execute
    f"Bash command failed. The command returned a non-zero exit code {result.exit_code}."
airflow.exceptions.AirflowException: Bash command failed. The command returned a non-zero exit code 2.
[2023-03-05T11:42:09.143+0000] {taskinstance.py:1323} INFO - Marking task as FAILED. dag_id=transform_fact_user, task_id=task_2, execution_date=20230305T114207, start_date=20230305T114208, end_date=20230305T114209
[2023-03-05T11:42:09.153+0000] {standard_task_runner.py:105} ERROR - Failed to execute job 45 for task task_2 (Bash command failed. The command returned a non-zero exit code 2.; 2791)
[2023-03-05T11:42:09.193+0000] {local_task_job.py:208} INFO - Task exited with return code 1
[2023-03-05T11:42:09.210+0000] {taskinstance.py:2578} INFO - 0 downstream tasks scheduled from follow-on schedule check
