[2023-03-26T09:42:09.305+0000] {taskinstance.py:1083} INFO - Dependencies all met for <TaskInstance: ge_t_postgres_fact_user.ge_t_postgres_fact_user manual__2023-03-26T09:42:03.320353+00:00 [queued]>
[2023-03-26T09:42:09.316+0000] {taskinstance.py:1083} INFO - Dependencies all met for <TaskInstance: ge_t_postgres_fact_user.ge_t_postgres_fact_user manual__2023-03-26T09:42:03.320353+00:00 [queued]>
[2023-03-26T09:42:09.318+0000] {taskinstance.py:1279} INFO - 
--------------------------------------------------------------------------------
[2023-03-26T09:42:09.319+0000] {taskinstance.py:1280} INFO - Starting attempt 1 of 1
[2023-03-26T09:42:09.320+0000] {taskinstance.py:1281} INFO - 
--------------------------------------------------------------------------------
[2023-03-26T09:42:09.334+0000] {taskinstance.py:1300} INFO - Executing <Task(PythonOperator): ge_t_postgres_fact_user> on 2023-03-26 09:42:03.320353+00:00
[2023-03-26T09:42:09.344+0000] {standard_task_runner.py:55} INFO - Started process 2099 to run task
[2023-03-26T09:42:09.352+0000] {standard_task_runner.py:82} INFO - Running: ['***', 'tasks', 'run', 'ge_t_postgres_fact_user', 'ge_t_postgres_fact_user', 'manual__2023-03-26T09:42:03.320353+00:00', '--job-id', '144', '--raw', '--subdir', 'DAGS_FOLDER/ge_t_postgres_fact_user.py', '--cfg-path', '/tmp/tmpjqqttivq']
[2023-03-26T09:42:09.355+0000] {standard_task_runner.py:83} INFO - Job 144: Subtask ge_t_postgres_fact_user
[2023-03-26T09:42:09.433+0000] {task_command.py:388} INFO - Running <TaskInstance: ge_t_postgres_fact_user.ge_t_postgres_fact_user manual__2023-03-26T09:42:03.320353+00:00 [running]> on host 07b54bb2b8de
[2023-03-26T09:42:09.501+0000] {taskinstance.py:1509} INFO - Exporting the following env vars:
AIRFLOW_CTX_DAG_EMAIL=***@example.com
AIRFLOW_CTX_DAG_OWNER=***
AIRFLOW_CTX_DAG_ID=ge_t_postgres_fact_user
AIRFLOW_CTX_TASK_ID=ge_t_postgres_fact_user
AIRFLOW_CTX_EXECUTION_DATE=2023-03-26T09:42:03.320353+00:00
AIRFLOW_CTX_TRY_NUMBER=1
AIRFLOW_CTX_DAG_RUN_ID=manual__2023-03-26T09:42:03.320353+00:00
[2023-03-26T09:42:09.505+0000] {util.py:1938} INFO - Could not find local context root directory
[2023-03-26T09:42:09.507+0000] {base.py:2129} INFO - Created temporary directory '/tmp/tmp1s97035r' for ephemeral docs site
[2023-03-26T09:42:09.509+0000] {abstract_data_context.py:5425} INFO - EphemeralDataContext has not implemented `_load_fluent_config()` returning empty `GxConfig`
[2023-03-26T09:42:09.511+0000] {config.py:91} INFO - Loading 'datasources' ->
{}
[2023-03-26T09:42:09.512+0000] {config.py:149} INFO - Loaded 'datasources' ->
{}
[2023-03-26T09:42:09.531+0000] {taskinstance.py:1768} ERROR - Task failed with exception
Traceback (most recent call last):
  File "/home/airflow/.local/lib/python3.7/site-packages/airflow/operators/python.py", line 175, in execute
    return_value = self.execute_callable()
  File "/home/airflow/.local/lib/python3.7/site-packages/airflow/operators/python.py", line 192, in execute_callable
    return self.python_callable(*self.op_args, **self.op_kwargs)
  File "/opt/airflow/dags/ge_t_postgres_fact_user.py", line 68, in ge_t_postgres_fact_user
    validator = context.get_validator(batch_request=batch_request)
  File "/home/airflow/.local/lib/python3.7/site-packages/great_expectations/data_context/data_context/abstract_data_context.py", line 2451, in get_validator
    **kwargs,
  File "/home/airflow/.local/lib/python3.7/site-packages/great_expectations/core/usage_statistics/usage_statistics.py", line 318, in usage_statistics_wrapped_method
    result = func(*args, **kwargs)
  File "/home/airflow/.local/lib/python3.7/site-packages/great_expectations/data_context/data_context/abstract_data_context.py", line 2618, in get_batch_list
    **kwargs,
  File "/home/airflow/.local/lib/python3.7/site-packages/great_expectations/data_context/data_context/abstract_data_context.py", line 2672, in _get_batch_list
    "The given datasource could not be retrieved from the DataContext; "
great_expectations.exceptions.exceptions.DatasourceError: Cannot initialize datasource postgres_aws, error: The given datasource could not be retrieved from the DataContext; please confirm that your configuration is accurate.
[2023-03-26T09:42:09.547+0000] {taskinstance.py:1323} INFO - Marking task as FAILED. dag_id=ge_t_postgres_fact_user, task_id=ge_t_postgres_fact_user, execution_date=20230326T094203, start_date=20230326T094209, end_date=20230326T094209
[2023-03-26T09:42:09.557+0000] {standard_task_runner.py:105} ERROR - Failed to execute job 144 for task ge_t_postgres_fact_user (Cannot initialize datasource postgres_aws, error: The given datasource could not be retrieved from the DataContext; please confirm that your configuration is accurate.; 2099)
[2023-03-26T09:42:09.615+0000] {local_task_job.py:208} INFO - Task exited with return code 1
[2023-03-26T09:42:09.631+0000] {taskinstance.py:2578} INFO - 0 downstream tasks scheduled from follow-on schedule check
