[2023-03-26T09:27:35.776+0000] {taskinstance.py:1083} INFO - Dependencies all met for <TaskInstance: ge_t_postgres_fact_user.ge_t_postgres_fact_user manual__2023-03-26T09:27:30.118437+00:00 [queued]>
[2023-03-26T09:27:35.782+0000] {taskinstance.py:1083} INFO - Dependencies all met for <TaskInstance: ge_t_postgres_fact_user.ge_t_postgres_fact_user manual__2023-03-26T09:27:30.118437+00:00 [queued]>
[2023-03-26T09:27:35.784+0000] {taskinstance.py:1279} INFO - 
--------------------------------------------------------------------------------
[2023-03-26T09:27:35.785+0000] {taskinstance.py:1280} INFO - Starting attempt 1 of 1
[2023-03-26T09:27:35.786+0000] {taskinstance.py:1281} INFO - 
--------------------------------------------------------------------------------
[2023-03-26T09:27:35.796+0000] {taskinstance.py:1300} INFO - Executing <Task(PythonOperator): ge_t_postgres_fact_user> on 2023-03-26 09:27:30.118437+00:00
[2023-03-26T09:27:35.808+0000] {standard_task_runner.py:55} INFO - Started process 1170 to run task
[2023-03-26T09:27:35.812+0000] {standard_task_runner.py:82} INFO - Running: ['***', 'tasks', 'run', 'ge_t_postgres_fact_user', 'ge_t_postgres_fact_user', 'manual__2023-03-26T09:27:30.118437+00:00', '--job-id', '142', '--raw', '--subdir', 'DAGS_FOLDER/ge_t_postgres_fact_user.py', '--cfg-path', '/tmp/tmpvolfrqul']
[2023-03-26T09:27:35.815+0000] {standard_task_runner.py:83} INFO - Job 142: Subtask ge_t_postgres_fact_user
[2023-03-26T09:27:35.885+0000] {task_command.py:388} INFO - Running <TaskInstance: ge_t_postgres_fact_user.ge_t_postgres_fact_user manual__2023-03-26T09:27:30.118437+00:00 [running]> on host 07b54bb2b8de
[2023-03-26T09:27:35.940+0000] {taskinstance.py:1509} INFO - Exporting the following env vars:
AIRFLOW_CTX_DAG_EMAIL=***@example.com
AIRFLOW_CTX_DAG_OWNER=***
AIRFLOW_CTX_DAG_ID=ge_t_postgres_fact_user
AIRFLOW_CTX_TASK_ID=ge_t_postgres_fact_user
AIRFLOW_CTX_EXECUTION_DATE=2023-03-26T09:27:30.118437+00:00
AIRFLOW_CTX_TRY_NUMBER=1
AIRFLOW_CTX_DAG_RUN_ID=manual__2023-03-26T09:27:30.118437+00:00
[2023-03-26T09:27:35.942+0000] {util.py:1938} INFO - Could not find local context root directory
[2023-03-26T09:27:35.950+0000] {base.py:2129} INFO - Created temporary directory '/tmp/tmpiadbbz0o' for ephemeral docs site
[2023-03-26T09:27:35.952+0000] {abstract_data_context.py:5425} INFO - EphemeralDataContext has not implemented `_load_fluent_config()` returning empty `GxConfig`
[2023-03-26T09:27:35.953+0000] {config.py:91} INFO - Loading 'datasources' ->
{}
[2023-03-26T09:27:35.954+0000] {config.py:149} INFO - Loaded 'datasources' ->
{}
[2023-03-26T09:27:35.970+0000] {taskinstance.py:1768} ERROR - Task failed with exception
Traceback (most recent call last):
  File "/home/airflow/.local/lib/python3.7/site-packages/airflow/operators/python.py", line 175, in execute
    return_value = self.execute_callable()
  File "/home/airflow/.local/lib/python3.7/site-packages/airflow/operators/python.py", line 192, in execute_callable
    return self.python_callable(*self.op_args, **self.op_kwargs)
  File "/opt/airflow/dags/ge_t_postgres_fact_user.py", line 68, in ge_t_postgres_fact_user
    validator = context.get_validator(batch_request=batch_request)
  File "/home/airflow/.local/lib/python3.7/site-packages/great_expectations/data_context/data_context/abstract_data_context.py", line 2451, in get_validator
    **kwargs,
  File "/home/airflow/.local/lib/python3.7/site-packages/great_expectations/core/usage_statistics/usage_statistics.py", line 318, in usage_statistics_wrapped_method
    result = func(*args, **kwargs)
  File "/home/airflow/.local/lib/python3.7/site-packages/great_expectations/data_context/data_context/abstract_data_context.py", line 2618, in get_batch_list
    **kwargs,
  File "/home/airflow/.local/lib/python3.7/site-packages/great_expectations/data_context/data_context/abstract_data_context.py", line 2672, in _get_batch_list
    "The given datasource could not be retrieved from the DataContext; "
great_expectations.exceptions.exceptions.DatasourceError: Cannot initialize datasource postgres_aws, error: The given datasource could not be retrieved from the DataContext; please confirm that your configuration is accurate.
[2023-03-26T09:27:35.984+0000] {taskinstance.py:1323} INFO - Marking task as FAILED. dag_id=ge_t_postgres_fact_user, task_id=ge_t_postgres_fact_user, execution_date=20230326T092730, start_date=20230326T092735, end_date=20230326T092735
[2023-03-26T09:27:35.993+0000] {standard_task_runner.py:105} ERROR - Failed to execute job 142 for task ge_t_postgres_fact_user (Cannot initialize datasource postgres_aws, error: The given datasource could not be retrieved from the DataContext; please confirm that your configuration is accurate.; 1170)
[2023-03-26T09:27:36.025+0000] {local_task_job.py:208} INFO - Task exited with return code 1
[2023-03-26T09:27:36.042+0000] {taskinstance.py:2578} INFO - 0 downstream tasks scheduled from follow-on schedule check
