[2023-03-26T08:15:49.558+0000] {taskinstance.py:1083} INFO - Dependencies all met for <TaskInstance: ge_t_postgres_fact_user.set_up_source manual__2023-03-26T08:15:46.319845+00:00 [queued]>
[2023-03-26T08:15:49.567+0000] {taskinstance.py:1083} INFO - Dependencies all met for <TaskInstance: ge_t_postgres_fact_user.set_up_source manual__2023-03-26T08:15:46.319845+00:00 [queued]>
[2023-03-26T08:15:49.573+0000] {taskinstance.py:1279} INFO - 
--------------------------------------------------------------------------------
[2023-03-26T08:15:49.575+0000] {taskinstance.py:1280} INFO - Starting attempt 1 of 1
[2023-03-26T08:15:49.576+0000] {taskinstance.py:1281} INFO - 
--------------------------------------------------------------------------------
[2023-03-26T08:15:49.586+0000] {taskinstance.py:1300} INFO - Executing <Task(PythonOperator): set_up_source> on 2023-03-26 08:15:46.319845+00:00
[2023-03-26T08:15:49.598+0000] {standard_task_runner.py:55} INFO - Started process 3509 to run task
[2023-03-26T08:15:49.601+0000] {standard_task_runner.py:82} INFO - Running: ['***', 'tasks', 'run', 'ge_t_postgres_fact_user', 'set_up_source', 'manual__2023-03-26T08:15:46.319845+00:00', '--job-id', '124', '--raw', '--subdir', 'DAGS_FOLDER/ge_t_postgres_fact_user.py', '--cfg-path', '/tmp/tmpx_ol1e3o']
[2023-03-26T08:15:49.603+0000] {standard_task_runner.py:83} INFO - Job 124: Subtask set_up_source
[2023-03-26T08:15:49.683+0000] {task_command.py:388} INFO - Running <TaskInstance: ge_t_postgres_fact_user.set_up_source manual__2023-03-26T08:15:46.319845+00:00 [running]> on host 79c6630d655a
[2023-03-26T08:15:49.745+0000] {taskinstance.py:1509} INFO - Exporting the following env vars:
AIRFLOW_CTX_DAG_EMAIL=***@example.com
AIRFLOW_CTX_DAG_OWNER=***
AIRFLOW_CTX_DAG_ID=ge_t_postgres_fact_user
AIRFLOW_CTX_TASK_ID=set_up_source
AIRFLOW_CTX_EXECUTION_DATE=2023-03-26T08:15:46.319845+00:00
AIRFLOW_CTX_TRY_NUMBER=1
AIRFLOW_CTX_DAG_RUN_ID=manual__2023-03-26T08:15:46.319845+00:00
[2023-03-26T08:15:49.748+0000] {util.py:1938} INFO - Could not find local context root directory
[2023-03-26T08:15:49.750+0000] {base.py:2129} INFO - Created temporary directory '/tmp/tmpzwafhl7l' for ephemeral docs site
[2023-03-26T08:15:49.757+0000] {abstract_data_context.py:5425} INFO - EphemeralDataContext has not implemented `_load_fluent_config()` returning empty `GxConfig`
[2023-03-26T08:15:49.759+0000] {config.py:91} INFO - Loading 'datasources' ->
{}
[2023-03-26T08:15:49.760+0000] {config.py:149} INFO - Loaded 'datasources' ->
{}
[2023-03-26T08:15:49.778+0000] {taskinstance.py:1768} ERROR - Task failed with exception
Traceback (most recent call last):
  File "/home/airflow/.local/lib/python3.7/site-packages/airflow/operators/python.py", line 175, in execute
    return_value = self.execute_callable()
  File "/home/airflow/.local/lib/python3.7/site-packages/airflow/operators/python.py", line 192, in execute_callable
    return self.python_callable(*self.op_args, **self.op_kwargs)
  File "/opt/airflow/dags/ge_t_postgres_fact_user.py", line 66, in ge_t_postgres_fact_user
    validator = context.get_validator(batch_request=batch_request)
  File "/home/airflow/.local/lib/python3.7/site-packages/great_expectations/data_context/data_context/abstract_data_context.py", line 2451, in get_validator
    **kwargs,
  File "/home/airflow/.local/lib/python3.7/site-packages/great_expectations/core/usage_statistics/usage_statistics.py", line 318, in usage_statistics_wrapped_method
    result = func(*args, **kwargs)
  File "/home/airflow/.local/lib/python3.7/site-packages/great_expectations/data_context/data_context/abstract_data_context.py", line 2618, in get_batch_list
    **kwargs,
  File "/home/airflow/.local/lib/python3.7/site-packages/great_expectations/data_context/data_context/abstract_data_context.py", line 2672, in _get_batch_list
    "The given datasource could not be retrieved from the DataContext; "
great_expectations.exceptions.exceptions.DatasourceError: Cannot initialize datasource postgres_aws, error: The given datasource could not be retrieved from the DataContext; please confirm that your configuration is accurate.
[2023-03-26T08:15:49.793+0000] {taskinstance.py:1323} INFO - Marking task as FAILED. dag_id=ge_t_postgres_fact_user, task_id=set_up_source, execution_date=20230326T081546, start_date=20230326T081549, end_date=20230326T081549
[2023-03-26T08:15:49.802+0000] {standard_task_runner.py:105} ERROR - Failed to execute job 124 for task set_up_source (Cannot initialize datasource postgres_aws, error: The given datasource could not be retrieved from the DataContext; please confirm that your configuration is accurate.; 3509)
[2023-03-26T08:15:49.856+0000] {local_task_job.py:208} INFO - Task exited with return code 1
[2023-03-26T08:15:49.873+0000] {taskinstance.py:2578} INFO - 0 downstream tasks scheduled from follow-on schedule check
