[2023-03-26T07:45:49.108+0000] {taskinstance.py:1083} INFO - Dependencies all met for <TaskInstance: ge_t_postgres_fact_user.trialPythonGe scheduled__2023-03-25T00:00:00+00:00 [queued]>
[2023-03-26T07:45:49.118+0000] {taskinstance.py:1083} INFO - Dependencies all met for <TaskInstance: ge_t_postgres_fact_user.trialPythonGe scheduled__2023-03-25T00:00:00+00:00 [queued]>
[2023-03-26T07:45:49.120+0000] {taskinstance.py:1279} INFO - 
--------------------------------------------------------------------------------
[2023-03-26T07:45:49.121+0000] {taskinstance.py:1280} INFO - Starting attempt 1 of 2
[2023-03-26T07:45:49.123+0000] {taskinstance.py:1281} INFO - 
--------------------------------------------------------------------------------
[2023-03-26T07:45:49.137+0000] {taskinstance.py:1300} INFO - Executing <Task(PythonOperator): trialPythonGe> on 2023-03-25 00:00:00+00:00
[2023-03-26T07:45:49.148+0000] {standard_task_runner.py:55} INFO - Started process 1605 to run task
[2023-03-26T07:45:49.156+0000] {standard_task_runner.py:82} INFO - Running: ['***', 'tasks', 'run', 'ge_t_postgres_fact_user', 'trialPythonGe', 'scheduled__2023-03-25T00:00:00+00:00', '--job-id', '117', '--raw', '--subdir', 'DAGS_FOLDER/ge_t_postgres_fact_user.py', '--cfg-path', '/tmp/tmpvivizlej']
[2023-03-26T07:45:49.158+0000] {standard_task_runner.py:83} INFO - Job 117: Subtask trialPythonGe
[2023-03-26T07:45:49.256+0000] {task_command.py:388} INFO - Running <TaskInstance: ge_t_postgres_fact_user.trialPythonGe scheduled__2023-03-25T00:00:00+00:00 [running]> on host 79c6630d655a
[2023-03-26T07:45:49.380+0000] {taskinstance.py:1509} INFO - Exporting the following env vars:
AIRFLOW_CTX_DAG_EMAIL=***@example.com
AIRFLOW_CTX_DAG_OWNER=***
AIRFLOW_CTX_DAG_ID=ge_t_postgres_fact_user
AIRFLOW_CTX_TASK_ID=trialPythonGe
AIRFLOW_CTX_EXECUTION_DATE=2023-03-25T00:00:00+00:00
AIRFLOW_CTX_TRY_NUMBER=1
AIRFLOW_CTX_DAG_RUN_ID=scheduled__2023-03-25T00:00:00+00:00
[2023-03-26T07:45:49.385+0000] {util.py:1938} INFO - Could not find local context root directory
[2023-03-26T07:45:49.388+0000] {base.py:2129} INFO - Created temporary directory '/tmp/tmpjzuf1x11' for ephemeral docs site
[2023-03-26T07:45:49.392+0000] {abstract_data_context.py:5425} INFO - EphemeralDataContext has not implemented `_load_fluent_config()` returning empty `GxConfig`
[2023-03-26T07:45:49.394+0000] {config.py:91} INFO - Loading 'datasources' ->
{}
[2023-03-26T07:45:49.400+0000] {config.py:149} INFO - Loaded 'datasources' ->
{}
[2023-03-26T07:45:49.422+0000] {taskinstance.py:1768} ERROR - Task failed with exception
Traceback (most recent call last):
  File "/home/airflow/.local/lib/python3.7/site-packages/airflow/operators/python.py", line 175, in execute
    return_value = self.execute_callable()
  File "/home/airflow/.local/lib/python3.7/site-packages/airflow/operators/python.py", line 192, in execute_callable
    return self.python_callable(*self.op_args, **self.op_kwargs)
  File "/opt/airflow/dags/ge_t_postgres_fact_user.py", line 20, in ge_t_postgres_fact_user
    validator = context.get_validator(batch_request=batch_request)
  File "/home/airflow/.local/lib/python3.7/site-packages/great_expectations/data_context/data_context/abstract_data_context.py", line 2451, in get_validator
    **kwargs,
  File "/home/airflow/.local/lib/python3.7/site-packages/great_expectations/core/usage_statistics/usage_statistics.py", line 318, in usage_statistics_wrapped_method
    result = func(*args, **kwargs)
  File "/home/airflow/.local/lib/python3.7/site-packages/great_expectations/data_context/data_context/abstract_data_context.py", line 2618, in get_batch_list
    **kwargs,
  File "/home/airflow/.local/lib/python3.7/site-packages/great_expectations/data_context/data_context/abstract_data_context.py", line 2672, in _get_batch_list
    "The given datasource could not be retrieved from the DataContext; "
great_expectations.exceptions.exceptions.DatasourceError: Cannot initialize datasource postgres_aws, error: The given datasource could not be retrieved from the DataContext; please confirm that your configuration is accurate.
[2023-03-26T07:45:49.438+0000] {taskinstance.py:1323} INFO - Marking task as UP_FOR_RETRY. dag_id=ge_t_postgres_fact_user, task_id=trialPythonGe, execution_date=20230325T000000, start_date=20230326T074549, end_date=20230326T074549
[2023-03-26T07:45:49.448+0000] {standard_task_runner.py:105} ERROR - Failed to execute job 117 for task trialPythonGe (Cannot initialize datasource postgres_aws, error: The given datasource could not be retrieved from the DataContext; please confirm that your configuration is accurate.; 1605)
[2023-03-26T07:45:49.485+0000] {local_task_job.py:208} INFO - Task exited with return code 1
[2023-03-26T07:45:49.517+0000] {taskinstance.py:2578} INFO - 0 downstream tasks scheduled from follow-on schedule check
