[2023-03-25T14:41:23.056+0000] {taskinstance.py:1083} INFO - Dependencies all met for <TaskInstance: transform_fact_user.model.dbt_transform_postgres.fact_user manual__2023-03-25T14:41:21.485513+00:00 [queued]>
[2023-03-25T14:41:23.065+0000] {taskinstance.py:1083} INFO - Dependencies all met for <TaskInstance: transform_fact_user.model.dbt_transform_postgres.fact_user manual__2023-03-25T14:41:21.485513+00:00 [queued]>
[2023-03-25T14:41:23.067+0000] {taskinstance.py:1279} INFO - 
--------------------------------------------------------------------------------
[2023-03-25T14:41:23.069+0000] {taskinstance.py:1280} INFO - Starting attempt 1 of 1
[2023-03-25T14:41:23.071+0000] {taskinstance.py:1281} INFO - 
--------------------------------------------------------------------------------
[2023-03-25T14:41:23.082+0000] {taskinstance.py:1300} INFO - Executing <Task(BashOperator): model.dbt_transform_postgres.fact_user> on 2023-03-25 14:41:21.485513+00:00
[2023-03-25T14:41:23.091+0000] {standard_task_runner.py:55} INFO - Started process 172 to run task
[2023-03-25T14:41:23.096+0000] {standard_task_runner.py:82} INFO - Running: ['***', 'tasks', 'run', 'transform_fact_user', 'model.dbt_transform_postgres.fact_user', 'manual__2023-03-25T14:41:21.485513+00:00', '--job-id', '91', '--raw', '--subdir', 'DAGS_FOLDER/transform_fact_user.py', '--cfg-path', '/tmp/tmpy1aau0v2']
[2023-03-25T14:41:23.098+0000] {standard_task_runner.py:83} INFO - Job 91: Subtask model.dbt_transform_postgres.fact_user
[2023-03-25T14:41:23.186+0000] {task_command.py:388} INFO - Running <TaskInstance: transform_fact_user.model.dbt_transform_postgres.fact_user manual__2023-03-25T14:41:21.485513+00:00 [running]> on host 42dbb1dd359f
[2023-03-25T14:41:23.257+0000] {taskinstance.py:1509} INFO - Exporting the following env vars:
AIRFLOW_CTX_DAG_OWNER=***
AIRFLOW_CTX_DAG_ID=transform_fact_user
AIRFLOW_CTX_TASK_ID=model.dbt_transform_postgres.fact_user
AIRFLOW_CTX_EXECUTION_DATE=2023-03-25T14:41:21.485513+00:00
AIRFLOW_CTX_TRY_NUMBER=1
AIRFLOW_CTX_DAG_RUN_ID=manual__2023-03-25T14:41:21.485513+00:00
[2023-03-25T14:41:23.260+0000] {subprocess.py:63} INFO - Tmp dir root location: 
 /tmp
[2023-03-25T14:41:23.263+0000] {subprocess.py:75} INFO - Running command: ['/bin/bash', '-c', 'cd /opt/***/dbt_transform_postgres && dbt run --models fact_user']
[2023-03-25T14:41:23.284+0000] {subprocess.py:86} INFO - Output:
[2023-03-25T14:41:24.773+0000] {subprocess.py:93} INFO - [0m14:41:24  Encountered an error while reading profiles:
[2023-03-25T14:41:24.774+0000] {subprocess.py:93} INFO -   ERROR: Runtime Error
[2023-03-25T14:41:24.776+0000] {subprocess.py:93} INFO -   Credentials in profile "dbt_transform_postgres", target "dev" invalid: 1993 is not of type 'string'Defined profiles:
[2023-03-25T14:41:24.777+0000] {subprocess.py:93} INFO -  - dbt_transform_postgres
[2023-03-25T14:41:24.779+0000] {subprocess.py:93} INFO - For more information on configuring profiles, please consult the dbt docs:
[2023-03-25T14:41:24.780+0000] {subprocess.py:93} INFO - 
[2023-03-25T14:41:24.786+0000] {subprocess.py:93} INFO - https://docs.getdbt.com/docs/configure-your-profile
[2023-03-25T14:41:24.787+0000] {subprocess.py:93} INFO - 
[2023-03-25T14:41:24.788+0000] {subprocess.py:93} INFO - [0m14:41:24  Encountered an error:
[2023-03-25T14:41:24.790+0000] {subprocess.py:93} INFO - Runtime Error
[2023-03-25T14:41:24.791+0000] {subprocess.py:93} INFO -   Could not run dbt
[2023-03-25T14:41:24.904+0000] {subprocess.py:97} INFO - Command exited with return code 2
[2023-03-25T14:41:24.918+0000] {taskinstance.py:1768} ERROR - Task failed with exception
Traceback (most recent call last):
  File "/home/airflow/.local/lib/python3.7/site-packages/airflow/operators/bash.py", line 197, in execute
    f"Bash command failed. The command returned a non-zero exit code {result.exit_code}."
airflow.exceptions.AirflowException: Bash command failed. The command returned a non-zero exit code 2.
[2023-03-25T14:41:24.923+0000] {taskinstance.py:1323} INFO - Marking task as FAILED. dag_id=transform_fact_user, task_id=model.dbt_transform_postgres.fact_user, execution_date=20230325T144121, start_date=20230325T144123, end_date=20230325T144124
[2023-03-25T14:41:24.944+0000] {standard_task_runner.py:105} ERROR - Failed to execute job 91 for task model.dbt_transform_postgres.fact_user (Bash command failed. The command returned a non-zero exit code 2.; 172)
[2023-03-25T14:41:24.969+0000] {local_task_job.py:208} INFO - Task exited with return code 1
[2023-03-25T14:41:24.996+0000] {taskinstance.py:2578} INFO - 0 downstream tasks scheduled from follow-on schedule check
