[2023-03-26T08:14:17.118+0000] {taskinstance.py:1083} INFO - Dependencies all met for <TaskInstance: ge_t_postgres_fact_user.set_up_source manual__2023-03-26T08:14:14.349879+00:00 [queued]>
[2023-03-26T08:14:17.125+0000] {taskinstance.py:1083} INFO - Dependencies all met for <TaskInstance: ge_t_postgres_fact_user.set_up_source manual__2023-03-26T08:14:14.349879+00:00 [queued]>
[2023-03-26T08:14:17.126+0000] {taskinstance.py:1279} INFO - 
--------------------------------------------------------------------------------
[2023-03-26T08:14:17.127+0000] {taskinstance.py:1280} INFO - Starting attempt 1 of 1
[2023-03-26T08:14:17.128+0000] {taskinstance.py:1281} INFO - 
--------------------------------------------------------------------------------
[2023-03-26T08:14:17.138+0000] {taskinstance.py:1300} INFO - Executing <Task(PythonOperator): set_up_source> on 2023-03-26 08:14:14.349879+00:00
[2023-03-26T08:14:17.148+0000] {standard_task_runner.py:55} INFO - Started process 3410 to run task
[2023-03-26T08:14:17.152+0000] {standard_task_runner.py:82} INFO - Running: ['***', 'tasks', 'run', 'ge_t_postgres_fact_user', 'set_up_source', 'manual__2023-03-26T08:14:14.349879+00:00', '--job-id', '123', '--raw', '--subdir', 'DAGS_FOLDER/ge_t_postgres_fact_user.py', '--cfg-path', '/tmp/tmpayot3pct']
[2023-03-26T08:14:17.177+0000] {standard_task_runner.py:83} INFO - Job 123: Subtask set_up_source
[2023-03-26T08:14:17.255+0000] {task_command.py:388} INFO - Running <TaskInstance: ge_t_postgres_fact_user.set_up_source manual__2023-03-26T08:14:14.349879+00:00 [running]> on host 79c6630d655a
[2023-03-26T08:14:17.314+0000] {taskinstance.py:1509} INFO - Exporting the following env vars:
AIRFLOW_CTX_DAG_EMAIL=***@example.com
AIRFLOW_CTX_DAG_OWNER=***
AIRFLOW_CTX_DAG_ID=ge_t_postgres_fact_user
AIRFLOW_CTX_TASK_ID=set_up_source
AIRFLOW_CTX_EXECUTION_DATE=2023-03-26T08:14:14.349879+00:00
AIRFLOW_CTX_TRY_NUMBER=1
AIRFLOW_CTX_DAG_RUN_ID=manual__2023-03-26T08:14:14.349879+00:00
[2023-03-26T08:14:17.318+0000] {util.py:1938} INFO - Could not find local context root directory
[2023-03-26T08:14:17.320+0000] {base.py:2129} INFO - Created temporary directory '/tmp/tmplan8_qon' for ephemeral docs site
[2023-03-26T08:14:17.323+0000] {abstract_data_context.py:5425} INFO - EphemeralDataContext has not implemented `_load_fluent_config()` returning empty `GxConfig`
[2023-03-26T08:14:17.324+0000] {config.py:91} INFO - Loading 'datasources' ->
{}
[2023-03-26T08:14:17.325+0000] {config.py:149} INFO - Loaded 'datasources' ->
{}
[2023-03-26T08:14:17.348+0000] {taskinstance.py:1768} ERROR - Task failed with exception
Traceback (most recent call last):
  File "/home/airflow/.local/lib/python3.7/site-packages/airflow/operators/python.py", line 175, in execute
    return_value = self.execute_callable()
  File "/home/airflow/.local/lib/python3.7/site-packages/airflow/operators/python.py", line 192, in execute_callable
    return self.python_callable(*self.op_args, **self.op_kwargs)
  File "/opt/airflow/dags/ge_t_postgres_fact_user.py", line 66, in ge_t_postgres_fact_user
    validator = context.get_validator(batch_request=batch_request)
  File "/home/airflow/.local/lib/python3.7/site-packages/great_expectations/data_context/data_context/abstract_data_context.py", line 2451, in get_validator
    **kwargs,
  File "/home/airflow/.local/lib/python3.7/site-packages/great_expectations/core/usage_statistics/usage_statistics.py", line 318, in usage_statistics_wrapped_method
    result = func(*args, **kwargs)
  File "/home/airflow/.local/lib/python3.7/site-packages/great_expectations/data_context/data_context/abstract_data_context.py", line 2618, in get_batch_list
    **kwargs,
  File "/home/airflow/.local/lib/python3.7/site-packages/great_expectations/data_context/data_context/abstract_data_context.py", line 2672, in _get_batch_list
    "The given datasource could not be retrieved from the DataContext; "
great_expectations.exceptions.exceptions.DatasourceError: Cannot initialize datasource postgres_aws, error: The given datasource could not be retrieved from the DataContext; please confirm that your configuration is accurate.
[2023-03-26T08:14:17.367+0000] {taskinstance.py:1323} INFO - Marking task as FAILED. dag_id=ge_t_postgres_fact_user, task_id=set_up_source, execution_date=20230326T081414, start_date=20230326T081417, end_date=20230326T081417
[2023-03-26T08:14:17.377+0000] {standard_task_runner.py:105} ERROR - Failed to execute job 123 for task set_up_source (Cannot initialize datasource postgres_aws, error: The given datasource could not be retrieved from the DataContext; please confirm that your configuration is accurate.; 3410)
[2023-03-26T08:14:17.406+0000] {local_task_job.py:208} INFO - Task exited with return code 1
[2023-03-26T08:14:17.430+0000] {taskinstance.py:2578} INFO - 0 downstream tasks scheduled from follow-on schedule check
