[2023-03-26T07:50:52.636+0000] {taskinstance.py:1083} INFO - Dependencies all met for <TaskInstance: ge_t_postgres_fact_user.trialPythonGe scheduled__2023-03-24T00:00:00+00:00 [queued]>
[2023-03-26T07:50:52.646+0000] {taskinstance.py:1083} INFO - Dependencies all met for <TaskInstance: ge_t_postgres_fact_user.trialPythonGe scheduled__2023-03-24T00:00:00+00:00 [queued]>
[2023-03-26T07:50:52.647+0000] {taskinstance.py:1279} INFO - 
--------------------------------------------------------------------------------
[2023-03-26T07:50:52.656+0000] {taskinstance.py:1280} INFO - Starting attempt 2 of 2
[2023-03-26T07:50:52.659+0000] {taskinstance.py:1281} INFO - 
--------------------------------------------------------------------------------
[2023-03-26T07:50:52.673+0000] {taskinstance.py:1300} INFO - Executing <Task(PythonOperator): trialPythonGe> on 2023-03-24 00:00:00+00:00
[2023-03-26T07:50:52.696+0000] {standard_task_runner.py:55} INFO - Started process 1956 to run task
[2023-03-26T07:50:52.716+0000] {standard_task_runner.py:82} INFO - Running: ['***', 'tasks', 'run', 'ge_t_postgres_fact_user', 'trialPythonGe', 'scheduled__2023-03-24T00:00:00+00:00', '--job-id', '121', '--raw', '--subdir', 'DAGS_FOLDER/ge_t_postgres_fact_user.py', '--cfg-path', '/tmp/tmpxnjha9zl']
[2023-03-26T07:50:52.720+0000] {standard_task_runner.py:83} INFO - Job 121: Subtask trialPythonGe
[2023-03-26T07:50:53.025+0000] {task_command.py:388} INFO - Running <TaskInstance: ge_t_postgres_fact_user.trialPythonGe scheduled__2023-03-24T00:00:00+00:00 [running]> on host 79c6630d655a
[2023-03-26T07:50:53.191+0000] {taskinstance.py:1509} INFO - Exporting the following env vars:
AIRFLOW_CTX_DAG_EMAIL=***@example.com
AIRFLOW_CTX_DAG_OWNER=***
AIRFLOW_CTX_DAG_ID=ge_t_postgres_fact_user
AIRFLOW_CTX_TASK_ID=trialPythonGe
AIRFLOW_CTX_EXECUTION_DATE=2023-03-24T00:00:00+00:00
AIRFLOW_CTX_TRY_NUMBER=2
AIRFLOW_CTX_DAG_RUN_ID=scheduled__2023-03-24T00:00:00+00:00
[2023-03-26T07:50:53.195+0000] {util.py:1938} INFO - Could not find local context root directory
[2023-03-26T07:50:53.199+0000] {base.py:2129} INFO - Created temporary directory '/tmp/tmp7zxn8_fj' for ephemeral docs site
[2023-03-26T07:50:53.207+0000] {abstract_data_context.py:5425} INFO - EphemeralDataContext has not implemented `_load_fluent_config()` returning empty `GxConfig`
[2023-03-26T07:50:53.210+0000] {config.py:91} INFO - Loading 'datasources' ->
{}
[2023-03-26T07:50:53.211+0000] {config.py:149} INFO - Loaded 'datasources' ->
{}
[2023-03-26T07:50:53.244+0000] {taskinstance.py:1768} ERROR - Task failed with exception
Traceback (most recent call last):
  File "/home/airflow/.local/lib/python3.7/site-packages/airflow/operators/python.py", line 175, in execute
    return_value = self.execute_callable()
  File "/home/airflow/.local/lib/python3.7/site-packages/airflow/operators/python.py", line 192, in execute_callable
    return self.python_callable(*self.op_args, **self.op_kwargs)
  File "/opt/airflow/dags/ge_t_postgres_fact_user.py", line 20, in ge_t_postgres_fact_user
    validator = context.get_validator(batch_request=batch_request)
  File "/home/airflow/.local/lib/python3.7/site-packages/great_expectations/data_context/data_context/abstract_data_context.py", line 2451, in get_validator
    **kwargs,
  File "/home/airflow/.local/lib/python3.7/site-packages/great_expectations/core/usage_statistics/usage_statistics.py", line 318, in usage_statistics_wrapped_method
    result = func(*args, **kwargs)
  File "/home/airflow/.local/lib/python3.7/site-packages/great_expectations/data_context/data_context/abstract_data_context.py", line 2618, in get_batch_list
    **kwargs,
  File "/home/airflow/.local/lib/python3.7/site-packages/great_expectations/data_context/data_context/abstract_data_context.py", line 2672, in _get_batch_list
    "The given datasource could not be retrieved from the DataContext; "
great_expectations.exceptions.exceptions.DatasourceError: Cannot initialize datasource postgres_aws, error: The given datasource could not be retrieved from the DataContext; please confirm that your configuration is accurate.
[2023-03-26T07:50:53.265+0000] {taskinstance.py:1323} INFO - Marking task as FAILED. dag_id=ge_t_postgres_fact_user, task_id=trialPythonGe, execution_date=20230324T000000, start_date=20230326T075052, end_date=20230326T075053
[2023-03-26T07:50:53.287+0000] {standard_task_runner.py:105} ERROR - Failed to execute job 121 for task trialPythonGe (Cannot initialize datasource postgres_aws, error: The given datasource could not be retrieved from the DataContext; please confirm that your configuration is accurate.; 1956)
[2023-03-26T07:50:53.345+0000] {local_task_job.py:208} INFO - Task exited with return code 1
[2023-03-26T07:50:53.378+0000] {taskinstance.py:2578} INFO - 0 downstream tasks scheduled from follow-on schedule check
