[2023-03-26T07:50:52.608+0000] {taskinstance.py:1083} INFO - Dependencies all met for <TaskInstance: ge_t_postgres_fact_user.trialPythonGe manual__2023-03-26T07:45:44.638452+00:00 [queued]>
[2023-03-26T07:50:52.625+0000] {taskinstance.py:1083} INFO - Dependencies all met for <TaskInstance: ge_t_postgres_fact_user.trialPythonGe manual__2023-03-26T07:45:44.638452+00:00 [queued]>
[2023-03-26T07:50:52.626+0000] {taskinstance.py:1279} INFO - 
--------------------------------------------------------------------------------
[2023-03-26T07:50:52.627+0000] {taskinstance.py:1280} INFO - Starting attempt 2 of 2
[2023-03-26T07:50:52.629+0000] {taskinstance.py:1281} INFO - 
--------------------------------------------------------------------------------
[2023-03-26T07:50:52.644+0000] {taskinstance.py:1300} INFO - Executing <Task(PythonOperator): trialPythonGe> on 2023-03-26 07:45:44.638452+00:00
[2023-03-26T07:50:52.663+0000] {standard_task_runner.py:55} INFO - Started process 1954 to run task
[2023-03-26T07:50:52.669+0000] {standard_task_runner.py:82} INFO - Running: ['***', 'tasks', 'run', 'ge_t_postgres_fact_user', 'trialPythonGe', 'manual__2023-03-26T07:45:44.638452+00:00', '--job-id', '119', '--raw', '--subdir', 'DAGS_FOLDER/ge_t_postgres_fact_user.py', '--cfg-path', '/tmp/tmpya551hn8']
[2023-03-26T07:50:52.672+0000] {standard_task_runner.py:83} INFO - Job 119: Subtask trialPythonGe
[2023-03-26T07:50:53.006+0000] {task_command.py:388} INFO - Running <TaskInstance: ge_t_postgres_fact_user.trialPythonGe manual__2023-03-26T07:45:44.638452+00:00 [running]> on host 79c6630d655a
[2023-03-26T07:50:53.189+0000] {taskinstance.py:1509} INFO - Exporting the following env vars:
AIRFLOW_CTX_DAG_EMAIL=***@example.com
AIRFLOW_CTX_DAG_OWNER=***
AIRFLOW_CTX_DAG_ID=ge_t_postgres_fact_user
AIRFLOW_CTX_TASK_ID=trialPythonGe
AIRFLOW_CTX_EXECUTION_DATE=2023-03-26T07:45:44.638452+00:00
AIRFLOW_CTX_TRY_NUMBER=2
AIRFLOW_CTX_DAG_RUN_ID=manual__2023-03-26T07:45:44.638452+00:00
[2023-03-26T07:50:53.193+0000] {util.py:1938} INFO - Could not find local context root directory
[2023-03-26T07:50:53.197+0000] {base.py:2129} INFO - Created temporary directory '/tmp/tmp99df2udb' for ephemeral docs site
[2023-03-26T07:50:53.205+0000] {abstract_data_context.py:5425} INFO - EphemeralDataContext has not implemented `_load_fluent_config()` returning empty `GxConfig`
[2023-03-26T07:50:53.209+0000] {config.py:91} INFO - Loading 'datasources' ->
{}
[2023-03-26T07:50:53.210+0000] {config.py:149} INFO - Loaded 'datasources' ->
{}
[2023-03-26T07:50:53.242+0000] {taskinstance.py:1768} ERROR - Task failed with exception
Traceback (most recent call last):
  File "/home/airflow/.local/lib/python3.7/site-packages/airflow/operators/python.py", line 175, in execute
    return_value = self.execute_callable()
  File "/home/airflow/.local/lib/python3.7/site-packages/airflow/operators/python.py", line 192, in execute_callable
    return self.python_callable(*self.op_args, **self.op_kwargs)
  File "/opt/airflow/dags/ge_t_postgres_fact_user.py", line 20, in ge_t_postgres_fact_user
    validator = context.get_validator(batch_request=batch_request)
  File "/home/airflow/.local/lib/python3.7/site-packages/great_expectations/data_context/data_context/abstract_data_context.py", line 2451, in get_validator
    **kwargs,
  File "/home/airflow/.local/lib/python3.7/site-packages/great_expectations/core/usage_statistics/usage_statistics.py", line 318, in usage_statistics_wrapped_method
    result = func(*args, **kwargs)
  File "/home/airflow/.local/lib/python3.7/site-packages/great_expectations/data_context/data_context/abstract_data_context.py", line 2618, in get_batch_list
    **kwargs,
  File "/home/airflow/.local/lib/python3.7/site-packages/great_expectations/data_context/data_context/abstract_data_context.py", line 2672, in _get_batch_list
    "The given datasource could not be retrieved from the DataContext; "
great_expectations.exceptions.exceptions.DatasourceError: Cannot initialize datasource postgres_aws, error: The given datasource could not be retrieved from the DataContext; please confirm that your configuration is accurate.
[2023-03-26T07:50:53.265+0000] {taskinstance.py:1323} INFO - Marking task as FAILED. dag_id=ge_t_postgres_fact_user, task_id=trialPythonGe, execution_date=20230326T074544, start_date=20230326T075052, end_date=20230326T075053
[2023-03-26T07:50:53.283+0000] {standard_task_runner.py:105} ERROR - Failed to execute job 119 for task trialPythonGe (Cannot initialize datasource postgres_aws, error: The given datasource could not be retrieved from the DataContext; please confirm that your configuration is accurate.; 1954)
[2023-03-26T07:50:53.348+0000] {local_task_job.py:208} INFO - Task exited with return code 1
[2023-03-26T07:50:53.379+0000] {taskinstance.py:2578} INFO - 0 downstream tasks scheduled from follow-on schedule check
